<?xml version="1.0" encoding="utf-8"?>
<!-- =================================================================================== -->
<!-- |    This document was autogenerated by xacro from xacro/test.xacro               | -->
<!-- |    EDITING THIS FILE BY HAND IS NOT RECOMMENDED                                 | -->
<!-- =================================================================================== -->
<robot name="robot_from_DH_table">
  <link name="base_link">
    <visual>
      <geometry>
        <cylinder length="0.5" radius="0.2"/>
      </geometry>
      <origin rpy="0 0 1" xyz="0 0 0"/>
      <material name="blue"/>
    </visual>
  </link>
  <link name="link_0">
    <visual>
      <geometry>
        <cylinder length="0.5" radius="0.2"/>
      </geometry>
      <origin rpy="0 0 1" xyz="0 0 0"/>
      <material name="blue"/>
    </visual>
  </link>
  <link name="link_1">
    <visual>
      <geometry>
        <cylinder length="0.5" radius="0.2"/>
      </geometry>
      <origin rpy="0 0 1" xyz="0 0 0"/>
      <material name="blue"/>
    </visual>
  </link>
  <joint name="base_link_to_link_0" type="fixed">
    <parent link="base_link"/>
    <child link="link_0"/>
    <axis xyz="0 0 1"/>
    <origin rpy="0 0 0" xyz="0 0 0"/>
  </joint>
  <joint name="link_0_to_link_1" type="continuous">
    <parent link="link_0"/>
    <child link="link_1"/>
    <axis xyz="0 0 1"/>
    <origin rpy="0.0 -0.0 0.0" xyz="0.0 0.0 0.0"/>
  </joint>
  <link name="link_2">
    <visual>
      <geometry>
        <cylinder length="0.5" radius="0.2"/>
      </geometry>
      <origin rpy="0 0 1" xyz="0 0 0"/>
      <material name="blue"/>
    </visual>
  </link>
  <joint name="link_1_to_link_2" type="continuous">
    <parent link="link_1"/>
    <child link="link_2"/>
    <axis xyz="0 0 1"/>
    <origin rpy="-1.57 -0.0 0.0" xyz="0.0 0.0 0.0"/>
  </joint>
  <link name="link_3">
    <visual>
      <geometry>
        <cylinder length="0.5" radius="0.2"/>
      </geometry>
      <origin rpy="0 0 1" xyz="0 0 0"/>
      <material name="blue"/>
    </visual>
  </link>
  <joint name="link_2_to_link_3" type="continuous">
    <parent link="link_2"/>
    <child link="link_3"/>
    <axis xyz="0 0 1"/>
    <origin rpy="0.0 -0.0 0.0" xyz="1.0 0.0 0.0"/>
  </joint>
</robot>

